Workbook

Sheet PLANILHA MODELO
G1: NÃO ALTERAR | M1: PREENCHER | P1: NÃO ALTERAR
B2: EMPRESA | C2: NOME | D2: FUNCAO | E2: LIDER DIRETO | F2: GERENCIA/DIRETORIA | G2: DATA ADMISSAO/MUDANÇA COTISTA NO PASSADO | H2: ANO AQUISITIVO INICIO | I2: ANO AQUISITIVO TERMINO | J2: INICIO PERIODO AQUISITIVO | K2: FIM PERIODO AQUISITIVO | L2: LIMITE AUSENCIA EFETIVA | M2: SALDO | N2: QUANTIDADE DE DIAS DE AUSÊNCIA PROGRAMADA | O2: INICIO AUSENCIA | P2: FIM AUSENCIA | Q2: DIAS PENDENTES | R2: STATUS | S2: OBSERVAÇÃO DE SALDO DE PERÍODOS ANTERIORES
B3: PHDE | C3: ADAILTON LUCAS GALINDO DE ANDRADE | D3: CONSULTOR DE PLANEJAMENTO PL | E3: TULIO RAFAEL MORAIS | F3: LEONARDO AUGUSTO OLIVEIRA DRUMOND | G3: 44986 | H3: 2024 | I3: 2025 | J3: =DATE($H3,MONTH($G3),DAY($G3)) -> 45352 | K3: =DATE($H3+1,MONTH($G3),DAY($G3)) -> 45717 | L3: 46387 | M3: 21 | N3: 21 | O3: 46368 | P3: =IF(OR(O3="",N3=""),"",O3+N3-1) -> 46388 | Q3: =IF($J3="","",MAX(0,$M3-SUMIFS($N:$N,$J:$J,$J3,$K:$K,$K3))) -> 0 | R3: =IF(OR($M3="",$N3=""),"",IF($N3>$M3,"EXCEDE SALDO",IF(OR($O3="",$P3=""),"OK",IF($P3<$O3,"DATAS INVÁLIDAS",IF($P3>$L3,"FORA DO PRAZO","OK"))))) -> FORA DO PRAZO | S3: =IF(OR($M3="",$N3=""),"",IF($N3>$M3,"EXCEDE SALDO",IF(OR($O3="",$P3=""),"OK",IF($P3<$O3,"DATAS INVÁLIDAS",IF($P3>$L3,"FORA DO PRAZO","OK"))))) -> FORA DO PRAZO
B4: PHDE | C4: ADAILTON LUCAS GALINDO DE ANDRADE | D4: CONSULTOR DE PLANEJAMENTO PL | E4: TULIO RAFAEL MORAIS | F4: LEONARDO AUGUSTO OLIVEIRA DRUMOND | G4: 44986 | H4: 2025 | I4: 2026 | J4: =DATE($H4,MONTH($G4),DAY($G4)) -> 45717 | K4: =DATE($H4+1,MONTH($G4),DAY($G4)) -> 46082 | L4: 46387 | M4: 35 | N4: 35 | O4: 46076 | P4: =IF(OR(O4="",N4=""),"",O4+N4-1) -> 46110 | Q4: =IF($J4="","",MAX(0,$M4-SUMIFS($N:$N,$J:$J,$J4,$K:$K,$K4))) -> 0 | R4: =IF(OR($M4="",$N4=""),"",IF($N4>$M4,"EXCEDE SALDO",IF(OR($O4="",$P4=""),"OK",IF($P4<$O4,"DATAS INVÁLIDAS",IF($P4>$L4,"FORA DO PRAZO","OK"))))) -> OK | S4: =IF(OR($M4="",$N4=""),"",IF($N4>$M4,"EXCEDE SALDO",IF(OR($O4="",$P4=""),"OK",IF($P4<$O4,"DATAS INVÁLIDAS",IF($P4>$L4,"FORA DO PRAZO","OK"))))) -> OK
B5: PHDE | C5: ALEX POSSIDONIO DA SILVA | D5: COORDENADOR DE PLANEJAMENTO | E5: DIEGO FIRME BERNARDES | F5: DIEGO FIRME BERNARDES | G5: 45722 | H5: 2025 | I5: 2026 | J5: =DATE($H5,MONTH($G5),DAY($G5)) -> 45722 | K5: =DATE($H5+1,MONTH($G5),DAY($G5)) -> 46087 | L5: =DATE(YEAR($K5)+1,MONTH($K5),DAY($K5)) -> 46452 | M5: 21 | N5: 21 | O5: 46188 | P5: =IF(OR(O5="",N5=""),"",O5+N5-1) -> 46208 | Q5: =IF($J5="","",MAX(0,$M5-SUMIFS($N:$N,$J:$J,$J5,$K:$K,$K5))) -> 0 | R5: =IF(OR($M5="",$N5=""),"",IF($N5>$M5,"EXCEDE SALDO",IF(OR($O5="",$P5=""),"OK",IF($P5<$O5,"DATAS INVÁLIDAS",IF($P5>$L5,"FORA DO PRAZO","OK"))))) -> OK | S5: =IF(OR($M5="",$N5=""),"",IF($N5>$M5,"EXCEDE SALDO",IF(OR($O5="",$P5=""),"OK",IF($P5<$O5,"DATAS INVÁLIDAS",IF($P5>$L5,"FORA DO PRAZO","OK"))))) -> OK
B6: PHDE | C6: ANA REGINA REZENDE CALDEIRA | D6: COORDENADORA DE MARKETING | E6: LUCAS ANDRADE BATISTA | F6: PEDRO HENRIQUE BRAGA DE MORAIS | G6: 45201 | H6: 2024 | I6: 2025 | J6: =DATE($H6,MONTH($G6),DAY($G6)) -> 45567 | K6: =DATE($H6+1,MONTH($G6),DAY($G6)) -> 45932 | L6: =DATE(YEAR($K6)+1,MONTH($K6),DAY($K6)) -> 46297 | M6: 21 | N6: 21 | O6: 46296 | P6: =IF(OR(O6="",N6=""),"",O6+N6-1) -> 46316 | Q6: =IF($J6="","",MAX(0,$M6-SUMIFS($N:$N,$J:$J,$J6,$K:$K,$K6))) -> 0 | R6: =IF(OR($M6="",$N6=""),"",IF($N6>$M6,"EXCEDE SALDO",IF(OR($O6="",$P6=""),"OK",IF($P6<$O6,"DATAS INVÁLIDAS",IF($P6>$L6,"FORA DO PRAZO","OK"))))) -> FORA DO PRAZO | S6: =IF(OR($M6="",$N6=""),"",IF($N6>$M6,"EXCEDE SALDO",IF(OR($O6="",$P6=""),"OK",IF($P6<$O6,"DATAS INVÁLIDAS",IF($P6>$L6,"FORA DO PRAZO","OK"))))) -> FORA DO PRAZO
B7: PHDE | C7: ANA REGINA REZENDE CALDEIRA | D7: COORDENADORA DE MARKETING | E7: LUCAS ANDRADE BATISTA | F7: PEDRO HENRIQUE BRAGA DE MORAIS | G7: 45201 | H7: 2025 | I7: 2026 | J7: =DATE($H7,MONTH($G7),DAY($G7)) -> 45932 | K7: =DATE($H7+1,MONTH($G7),DAY($G7)) -> 46297 | L7: =DATE(YEAR($K7)+1,MONTH($K7),DAY($K7)) -> 46662 | M7: 21 | N7: 21 | O7: 46296 | P7: =IF(OR(O7="",N7=""),"",O7+N7-1) -> 46316 | Q7: =IF($J7="","",MAX(0,$M7-SUMIFS($N:$N,$J:$J,$J7,$K:$K,$K7))) -> 0 | R7: =IF(OR($M7="",$N7=""),"",IF($N7>$M7,"EXCEDE SALDO",IF(OR($O7="",$P7=""),"OK",IF($P7<$O7,"DATAS INVÁLIDAS",IF($P7>$L7,"FORA DO PRAZO","OK"))))) -> OK | S7: =IF(OR($M7="",$N7=""),"",IF($N7>$M7,"EXCEDE SALDO",IF(OR($O7="",$P7=""),"OK",IF($P7<$O7,"DATAS INVÁLIDAS",IF($P7>$L7,"FORA DO PRAZO","OK"))))) -> OK
B8: PHDE | C8: ANDRE LUIZ COSTA GUIMARAES | D8: GERENTE DE PMO | E8: ANDRE LUIZ COSTA GUIMARAES | F8: PEDRO HENRIQUE BRAGA DE MORAIS | G8: 45474 | H8: 2024 | I8: 2025 | J8: =DATE($H8,MONTH($G8),DAY($G8)) -> 45474 | K8: =DATE($H8+1,MONTH($G8),DAY($G8)) -> 45839 | L8: =DATE(YEAR($K8)+1,MONTH($K8),DAY($K8)) -> 46204 | M8: 21 | N8: 7 | O8: 45971 | P8: =IF(OR(O8="",N8=""),"",O8+N8-1) -> 45977 | Q8: =IF($J8="","",MAX(0,$M8-SUMIFS($N:$N,$J:$J,$J8,$K:$K,$K8))) -> 0 | R8: =IF(OR($M8="",$N8=""),"",IF($N8>$M8,"EXCEDE SALDO",IF(OR($O8="",$P8=""),"OK",IF($P8<$O8,"DATAS INVÁLIDAS",IF($P8>$L8,"FORA DO PRAZO","OK"))))) -> OK | S8: =IF(OR($M8="",$N8=""),"",IF($N8>$M8,"EXCEDE SALDO",IF(OR($O8="",$P8=""),"OK",IF($P8<$O8,"DATAS INVÁLIDAS",IF($P8>$L8,"FORA DO PRAZO","OK"))))) -> OK
B9: PHDE | C9: ANDRE LUIZ COSTA GUIMARAES | D9: GERENTE DE PMO | E9: ANDRE LUIZ COSTA GUIMARAES | F9: PEDRO HENRIQUE BRAGA DE MORAIS | G9: 45474 | H9: 2024 | I9: 2025 | J9: =DATE($H9,MONTH($G9),DAY($G9)) -> 45474 | K9: =DATE($H9+1,MONTH($G9),DAY($G9)) -> 45839 | L9: =DATE(YEAR($K9)+1,MONTH($K9),DAY($K9)) -> 46204 | M9: 14 | N9: 7 | O9: 46076 | P9: =IF(OR(O9="",N9=""),"",O9+N9-1) -> 46082 | Q9: =IF($J9="","",MAX(0,$M9-SUMIFS($N:$N,$J:$J,$J9,$K:$K,$K9))) -> 0 | R9: =IF(OR($M9="",$N9=""),"",IF($N9>$M9,"EXCEDE SALDO",IF(OR($O9="",$P9=""),"OK",IF($P9<$O9,"DATAS INVÁLIDAS",IF($P9>$L9,"FORA DO PRAZO","OK"))))) -> OK | S9: =IF(OR($M9="",$N9=""),"",IF($N9>$M9,"EXCEDE SALDO",IF(OR($O9="",$P9=""),"OK",IF($P9<$O9,"DATAS INVÁLIDAS",IF($P9>$L9,"FORA DO PRAZO","OK"))))) -> OK
B10: PHDE | C10: ANDRE LUIZ COSTA GUIMARAES | D10: GERENTE DE PMO | E10: ANDRE LUIZ COSTA GUIMARAES | F10: PEDRO HENRIQUE BRAGA DE MORAIS | G10: 45474 | H10: 2024 | I10: 2025 | J10: =DATE($H10,MONTH($G10),DAY($G10)) -> 45474 | K10: =DATE($H10+1,MONTH($G10),DAY($G10)) -> 45839 | L10: =DATE(YEAR($K10)+1,MONTH($K10),DAY($K10)) -> 46204 | M10: 7 | N10: 7 | O10: 46153 | P10: =IF(OR(O10="",N10=""),"",O10+N10-1) -> 46159 | Q10: =IF($J10="","",MAX(0,$M10-SUMIFS($N:$N,$J:$J,$J10,$K:$K,$K10))) -> 0 | R10: =IF(OR($M10="",$N10=""),"",IF($N10>$M10,"EXCEDE SALDO",IF(OR($O10="",$P10=""),"OK",IF($P10<$O10,"DATAS INVÁLIDAS",IF($P10>$L10,"FORA DO PRAZO","OK"))))) -> OK | S10: =IF(OR($M10="",$N10=""),"",IF($N10>$M10,"EXCEDE SALDO",IF(OR($O10="",$P10=""),"OK",IF($P10<$O10,"DATAS INVÁLIDAS",IF($P10>$L10,"FORA DO PRAZO","OK"))))) -> OK
B11: PHDE | C11: ANDRE LUIZ COSTA GUIMARAES | D11: GERENTE DE PMO | E11: ANDRE LUIZ COSTA GUIMARAES | F11: PEDRO HENRIQUE BRAGA DE MORAIS | G11: 45474 | H11: 2025 | I11: 2026 | J11: =DATE($H11,MONTH($G11),DAY($G11)) -> 45839 | K11: =DATE($H11+1,MONTH($G11),DAY($G11)) -> 46204 | L11: =DATE(YEAR($K11)+1,MONTH($K11),DAY($K11)) -> 46569 | M11: 21 | N11: 14 | O11: 46209 | P11: =IF(OR(O11="",N11=""),"",O11+N11-1) -> 46222 | Q11: =IF($J11="","",MAX(0,$M11-SUMIFS($N:$N,$J:$J,$J11,$K:$K,$K11))) -> 0 | R11: =IF(OR($M11="",$N11=""),"",IF($N11>$M11,"EXCEDE SALDO",IF(OR($O11="",$P11=""),"OK",IF($P11<$O11,"DATAS INVÁLIDAS",IF($P11>$L11,"FORA DO PRAZO","OK"))))) -> OK | S11: =IF(OR($M11="",$N11=""),"",IF($N11>$M11,"EXCEDE SALDO",IF(OR($O11="",$P11=""),"OK",IF($P11<$O11,"DATAS INVÁLIDAS",IF($P11>$L11,"FORA DO PRAZO","OK"))))) -> OK
B12: PHDE | C12: ARTHUR FARHAT BENEDITO | D12: ESPECIALISTA DE PLANEJAMENTO | E12: SILAS MOREIRA TUPINAMBÁ | F12: DIEGO FIRME BERNARDES | G12: 45903 | H12: 2025 | I12: 2026 | J12: =DATE($H12,MONTH($G12),DAY($G12)) -> 45903 | K12: =DATE($H12+1,MONTH($G12),DAY($G12)) -> 46268 | L12: 46387 | M12: 7 | N12: 7 | O12: 46090 | P12: =IF(OR(O12="",N12=""),"",O12+N12-1) -> 46096 | Q12: =IF($J12="","",MAX(0,$M12-SUMIFS($N:$N,$J:$J,$J12,$K:$K,$K12))) -> 0 | R12: =IF(OR($M12="",$N12=""),"",IF($N12>$M12,"EXCEDE SALDO",IF(OR($O12="",$P12=""),"OK",IF($P12<$O12,"DATAS INVÁLIDAS",IF($P12>$L12,"FORA DO PRAZO","OK"))))) -> OK | S12: =IF(OR($M12="",$N12=""),"",IF($N12>$M12,"EXCEDE SALDO",IF(OR($O12="",$P12=""),"OK",IF($P12<$O12,"DATAS INVÁLIDAS",IF($P12>$L12,"FORA DO PRAZO","OK"))))) -> OK
B13: PHDE | C13: ARTHUR JOSE TEIXEIRA ANDRADE | D13: ESPECIALISTA DE PLANEJAMENTO | E13: TULIO RAFAEL MORAIS | F13: LEONARDO AUGUSTO OLIVEIRA DRUMOND | G13: 45684 | H13: 2025 | I13: 2026 | J13: =DATE($H13,MONTH($G13),DAY($G13)) -> 45684 | K13: =DATE($H13+1,MONTH($G13),DAY($G13)) -> 46049 | L13: =DATE(YEAR($K13)+1,MONTH($K13),DAY($K13)) -> 46414 | M13: 6 | N13: 6 | O13: 46118 | P13: =IF(OR(O13="",N13=""),"",O13+N13-1) -> 46123 | Q13: =IF($J13="","",MAX(0,$M13-SUMIFS($N:$N,$J:$J,$J13,$K:$K,$K13))) -> 0 | R13: =IF(OR($M13="",$N13=""),"",IF($N13>$M13,"EXCEDE SALDO",IF(OR($O13="",$P13=""),"OK",IF($P13<$O13,"DATAS INVÁLIDAS",IF($P13>$L13,"FORA DO PRAZO","OK"))))) -> OK | S13: =IF(OR($M13="",$N13=""),"",IF($N13>$M13,"EXCEDE SALDO",IF(OR($O13="",$P13=""),"OK",IF($P13<$O13,"DATAS INVÁLIDAS",IF($P13>$L13,"FORA DO PRAZO","OK"))))) -> OK
B14: PHDE | C14: ARTUR VIEIRA JANUTH | D14: CONSULTOR DE PLANEJAMENTO SR | E14: DIOGO HENRIQUE SOARES | F14: LEONARDO AUGUSTO OLIVEIRA DRUMOND | G14: 45131 | H14: 2024 | I14: 2025 | J14: =DATE($H14,MONTH($G14),DAY($G14)) -> 45497 | K14: =DATE($H14+1,MONTH($G14),DAY($G14)) -> 45862 | L14: 46387 | M14: 21 | N14: 21 | O14: 46235 | P14: =IF(OR(O14="",N14=""),"",O14+N14-1) -> 46255 | Q14: =IF($J14="","",MAX(0,$M14-SUMIFS($N:$N,$J:$J,$J14,$K:$K,$K14))) -> 0 | R14: =IF(OR($M14="",$N14=""),"",IF($N14>$M14,"EXCEDE SALDO",IF(OR($O14="",$P14=""),"OK",IF($P14<$O14,"DATAS INVÁLIDAS",IF($P14>$L14,"FORA DO PRAZO","OK"))))) -> OK | S14: =IF(OR($M14="",$N14=""),"",IF($N14>$M14,"EXCEDE SALDO",IF(OR($O14="",$P14=""),"OK",IF($P14<$O14,"DATAS INVÁLIDAS",IF($P14>$L14,"FORA DO PRAZO","OK"))))) -> OK
B15: PHDE | C15: BRENDO HENRIQUE LOPES | D15: CONSULTOR BIM PL | E15: RONALDO MENDES MACHADO | F15: BRUNO ALBERTO AZEVEDO | G15: 45722 | H15: 2025 | I15: 2026 | J15: =DATE($H15,MONTH($G15),DAY($G15)) -> 45722 | K15: =DATE($H15+1,MONTH($G15),DAY($G15)) -> 46087 | L15: =DATE(YEAR($K15)+1,MONTH($K15),DAY($K15)) -> 46452 | M15: 21 | N15: 21 | O15: 46076 | P15: =IF(OR(O15="",N15=""),"",O15+N15-1) -> 46096 | Q15: =IF($J15="","",MAX(0,$M15-SUMIFS($N:$N,$J:$J,$J15,$K:$K,$K15))) -> 0 | R15: =IF(OR($M15="",$N15=""),"",IF($N15>$M15,"EXCEDE SALDO",IF(OR($O15="",$P15=""),"OK",IF($P15<$O15,"DATAS INVÁLIDAS",IF($P15>$L15,"FORA DO PRAZO","OK"))))) -> OK | S15: =IF(OR($M15="",$N15=""),"",IF($N15>$M15,"EXCEDE SALDO",IF(OR($O15="",$P15=""),"OK",IF($P15<$O15,"DATAS INVÁLIDAS",IF($P15>$L15,"FORA DO PRAZO","OK"))))) -> OK
B16: PHDE | C16: BRUNO ALBERTO AZEVEDO | D16: GERENTE EXECUTIVO | E16: BRUNO ALBERTO AZEVEDO | F16: PEDRO HENRIQUE BRAGA DE MORAIS | G16: 44750 | H16: 2024 | I16: 2025 | J16: =DATE($H16,MONTH($G16),DAY($G16)) -> 45481 | K16: =DATE($H16+1,MONTH($G16),DAY($G16)) -> 45846 | L16: =DATE(YEAR($K16)+1,MONTH($K16),DAY($K16)) -> 46211 | M16: 15 | N16: 15 | O16: 46223 | P16: =IF(OR(O16="",N16=""),"",O16+N16-1) -> 46237 | Q16: =IF($J16="","",MAX(0,$M16-SUMIFS($N:$N,$J:$J,$J16,$K:$K,$K16))) -> 0 | R16: =IF(OR($M16="",$N16=""),"",IF($N16>$M16,"EXCEDE SALDO",IF(OR($O16="",$P16=""),"OK",IF($P16<$O16,"DATAS INVÁLIDAS",IF($P16>$L16,"FORA DO PRAZO","OK"))))) -> FORA DO PRAZO | S16: =IF(OR($M16="",$N16=""),"",IF($N16>$M16,"EXCEDE SALDO",IF(OR($O16="",$P16=""),"OK",IF($P16<$O16,"DATAS INVÁLIDAS",IF($P16>$L16,"FORA DO PRAZO","OK"))))) -> FORA DO PRAZO
B17: PHDE | C17: BRUNO ALBERTO AZEVEDO | D17: GERENTE EXECUTIVO | E17: BRUNO ALBERTO AZEVEDO | F17: PEDRO HENRIQUE BRAGA DE MORAIS | G17: 44750 | H17: 2024 | I17: 2025 | J17: =DATE($H17,MONTH($G17),DAY($G17)) -> 45481 | K17: =DATE($H17+1,MONTH($G17),DAY($G17)) -> 45846 | L17: =DATE(YEAR($K17)+1,MONTH($K17),DAY($K17)) -> 46211 | M17: 7 | N17: 7 | O17: 46279 | P17: =IF(OR(O17="",N17=""),"",O17+N17-1) -> 46285 | Q17: =IF($J17="","",MAX(0,$M17-SUMIFS($N:$N,$J:$J,$J17,$K:$K,$K17))) -> 0 | R17: =IF(OR($M17="",$N17=""),"",IF($N17>$M17,"EXCEDE SALDO",IF(OR($O17="",$P17=""),"OK",IF($P17<$O17,"DATAS INVÁLIDAS",IF($P17>$L17,"FORA DO PRAZO","OK"))))) -> FORA DO PRAZO | S17: =IF(OR($M17="",$N17=""),"",IF($N17>$M17,"EXCEDE SALDO",IF(OR($O17="",$P17=""),"OK",IF($P17<$O17,"DATAS INVÁLIDAS",IF($P17>$L17,"FORA DO PRAZO","OK"))))) -> FORA DO PRAZO
B18: PHDE | C18: BRUNO ALBERTO AZEVEDO | D18: GERENTE EXECUTIVO | E18: BRUNO ALBERTO AZEVEDO | F18: PEDRO HENRIQUE BRAGA DE MORAIS | G18: 44750 | H18: 2025 | I18: 2026 | J18: =DATE($H18,MONTH($G18),DAY($G18)) -> 45846 | K18: =DATE($H18+1,MONTH($G18),DAY($G18)) -> 46211 | L18: =DATE(YEAR($K18)+1,MONTH($K18),DAY($K18)) -> 46576 | M18: 14 | N18: 14 | O18: 46384 | P18: =IF(OR(O18="",N18=""),"",O18+N18-1) -> 46397 | Q18: =IF($J18="","",MAX(0,$M18-SUMIFS($N:$N,$J:$J,$J18,$K:$K,$K18))) -> 0 | R18: =IF(OR($M18="",$N18=""),"",IF($N18>$M18,"EXCEDE SALDO",IF(OR($O18="",$P18=""),"OK",IF($P18<$O18,"DATAS INVÁLIDAS",IF($P18>$L18,"FORA DO PRAZO","OK"))))) -> OK | S18: =IF(OR($M18="",$N18=""),"",IF($N18>$M18,"EXCEDE SALDO",IF(OR($O18="",$P18=""),"OK",IF($P18<$O18,"DATAS INVÁLIDAS",IF($P18>$L18,"FORA DO PRAZO","OK"))))) -> OK
B19: PHDE | C19: DANIEL CARLOS SILVA | D19: CONSULTOR DE PLANEJAMENTO SR | E19: ALESSANDRO PEREIRA MOREIRA | F19: LEONARDO AUGUSTO OLIVEIRA DRUMOND | G19: 45198 | H19: 2024 | I19: 2025 | J19: =DATE($H19,MONTH($G19),DAY($G19)) -> 45564 | K19: =DATE($H19+1,MONTH($G19),DAY($G19)) -> 45929 | L19: 46387 | M19: 4 | N19: 4 | O19: 46139 | P19: =IF(OR(O19="",N19=""),"",O19+N19-1) -> 46142 | Q19: =IF($J19="","",MAX(0,$M19-SUMIFS($N:$N,$J:$J,$J19,$K:$K,$K19))) -> 0 | R19: =IF(OR($M19="",$N19=""),"",IF($N19>$M19,"EXCEDE SALDO",IF(OR($O19="",$P19=""),"OK",IF($P19<$O19,"DATAS INVÁLIDAS",IF($P19>$L19,"FORA DO PRAZO","OK"))))) -> OK | S19: =IF(OR($M19="",$N19=""),"",IF($N19>$M19,"EXCEDE SALDO",IF(OR($O19="",$P19=""),"OK",IF($P19<$O19,"DATAS INVÁLIDAS",IF($P19>$L19,"FORA DO PRAZO","OK"))))) -> OK
B20: PHDE | C20: DANIEL CARLOS SILVA | D20: CONSULTOR DE PLANEJAMENTO SR | E20: ALESSANDRO PEREIRA MOREIRA | F20: LEONARDO AUGUSTO OLIVEIRA DRUMOND | G20: 45198 | H20: 2025 | I20: 2026 | J20: =DATE($H20,MONTH($G20),DAY($G20)) -> 45929 | K20: =DATE($H20+1,MONTH($G20),DAY($G20)) -> 46294 | L20: 46387 | M20: 21 | N20: 21 | O20: 46143 | P20: =IF(OR(O20="",N20=""),"",O20+N20-1) -> 46163 | Q20: =IF($J20="","",MAX(0,$M20-SUMIFS($N:$N,$J:$J,$J20,$K:$K,$K20))) -> 0 | R20: =IF(OR($M20="",$N20=""),"",IF($N20>$M20,"EXCEDE SALDO",IF(OR($O20="",$P20=""),"OK",IF($P20<$O20,"DATAS INVÁLIDAS",IF($P20>$L20,"FORA DO PRAZO","OK"))))) -> OK | S20: =IF(OR($M20="",$N20=""),"",IF($N20>$M20,"EXCEDE SALDO",IF(OR($O20="",$P20=""),"OK",IF($P20<$O20,"DATAS INVÁLIDAS",IF($P20>$L20,"FORA DO PRAZO","OK"))))) -> OK
B21: PHDE | C21: DANIEL DOS SANTOS ALMEIDA | D21: COORDENADOR COMERCIAL | E21: DANIEL DOS SANTOS ALMEIDA | F21: PEDRO HENRIQUE BRAGA DE MORAIS | G21: 44797 | H21: 2024 | I21: 2025 | J21: =DATE($H21,MONTH($G21),DAY($G21)) -> 45528 | K21: =DATE($H21+1,MONTH($G21),DAY($G21)) -> 45893 | L21: =DATE(YEAR($K21)+1,MONTH($K21),DAY($K21)) -> 46258 | M21: 7 | N21: 7 | O21: 46163 | P21: =IF(OR(O21="",N21=""),"",O21+N21-1) -> 46169 | Q21: =IF($J21="","",MAX(0,$M21-SUMIFS($N:$N,$J:$J,$J21,$K:$K,$K21))) -> 0 | R21: =IF(OR($M21="",$N21=""),"",IF($N21>$M21,"EXCEDE SALDO",IF(OR($O21="",$P21=""),"OK",IF($P21<$O21,"DATAS INVÁLIDAS",IF($P21>$L21,"FORA DO PRAZO","OK"))))) -> OK | S21: =IF(OR($M21="",$N21=""),"",IF($N21>$M21,"EXCEDE SALDO",IF(OR($O21="",$P21=""),"OK",IF($P21<$O21,"DATAS INVÁLIDAS",IF($P21>$L21,"FORA DO PRAZO","OK"))))) -> OK
B22: PHDE | C22: DANIEL DOS SANTOS ALMEIDA | D22: COORDENADOR COMERCIAL | E22: DANIEL DOS SANTOS ALMEIDA | F22: PEDRO HENRIQUE BRAGA DE MORAIS | G22: 44797 | H22: 2024 | I22: 2025 | J22: =DATE($H22,MONTH($G22),DAY($G22)) -> 45528 | K22: =DATE($H22+1,MONTH($G22),DAY($G22)) -> 45893 | L22: =DATE(YEAR($K22)+1,MONTH($K22),DAY($K22)) -> 46258 | M22: 21 | N22: 7 | O22: 46170 | P22: =IF(OR(O22="",N22=""),"",O22+N22-1) -> 46176 | Q22: =IF($J22="","",MAX(0,$M22-SUMIFS($N:$N,$J:$J,$J22,$K:$K,$K22))) -> 7 | R22: =IF(OR($M22="",$N22=""),"",IF($N22>$M22,"EXCEDE SALDO",IF(OR($O22="",$P22=""),"OK",IF($P22<$O22,"DATAS INVÁLIDAS",IF($P22>$L22,"FORA DO PRAZO","OK"))))) -> OK | S22: =IF(OR($M22="",$N22=""),"",IF($N22>$M22,"EXCEDE SALDO",IF(OR($O22="",$P22=""),"OK",IF($P22<$O22,"DATAS INVÁLIDAS",IF($P22>$L22,"FORA DO PRAZO","OK"))))) -> OK
B23: PHDE | C23: DANIEL DOS SANTOS ALMEIDA | D23: COORDENADOR COMERCIAL | E23: DANIEL DOS SANTOS ALMEIDA | F23: PEDRO HENRIQUE BRAGA DE MORAIS | G23: 44797 | H23: 2025 | I23: 2026 | J23: =DATE($H23,MONTH($G23),DAY($G23)) -> 45893 | K23: =DATE($H23+1,MONTH($G23),DAY($G23)) -> 46258 | L23: =DATE(YEAR($K23)+1,MONTH($K23),DAY($K23)) -> 46623 | M23: 14 | N23: 7 | O23: 46339 | P23: =IF(OR(O23="",N23=""),"",O23+N23-1) -> 46345 | Q23: =IF($J23="","",MAX(0,$M23-SUMIFS($N:$N,$J:$J,$J23,$K:$K,$K23))) -> 7 | R23: =IF(OR($M23="",$N23=""),"",IF($N23>$M23,"EXCEDE SALDO",IF(OR($O23="",$P23=""),"OK",IF($P23<$O23,"DATAS INVÁLIDAS",IF($P23>$L23,"FORA DO PRAZO","OK"))))) -> OK | S23: =IF(OR($M23="",$N23=""),"",IF($N23>$M23,"EXCEDE SALDO",IF(OR($O23="",$P23=""),"OK",IF($P23<$O23,"DATAS INVÁLIDAS",IF($P23>$L23,"FORA DO PRAZO","OK"))))) -> OK
B24: PHDE | C24: DANIEL MIRANDA CABRAL DE SOUSA | D24: CONSULTOR DE PLANEJAMENTO PL | E24: RONALDO MENDES MACHADO | F24: BRUNO ALBERTO AZEVEDO | G24: 45722 | H24: 2025 | I24: 2026 | J24: =DATE($H24,MONTH($G24),DAY($G24)) -> 45722 | K24: =DATE($H24+1,MONTH($G24),DAY($G24)) -> 46087 | L24: =DATE(YEAR($K24)+1,MONTH($K24),DAY($K24)) -> 46452 | M24: 21 | N24: 14 | O24: 46209 | P24: =IF(OR(O24="",N24=""),"",O24+N24-1) -> 46222 | Q24: =IF($J24="","",MAX(0,$M24-SUMIFS($N:$N,$J:$J,$J24,$K:$K,$K24))) -> 0 | R24: =IF(OR($M24="",$N24=""),"",IF($N24>$M24,"EXCEDE SALDO",IF(OR($O24="",$P24=""),"OK",IF($P24<$O24,"DATAS INVÁLIDAS",IF($P24>$L24,"FORA DO PRAZO","OK"))))) -> OK | S24: =IF(OR($M24="",$N24=""),"",IF($N24>$M24,"EXCEDE SALDO",IF(OR($O24="",$P24=""),"OK",IF($P24<$O24,"DATAS INVÁLIDAS",IF($P24>$L24,"FORA DO PRAZO","OK"))))) -> OK
B25: PHDE | C25: DANIEL MIRANDA CABRAL DE SOUSA | D25: CONSULTOR DE PLANEJAMENTO PL | E25: RONALDO MENDES MACHADO | F25: BRUNO ALBERTO AZEVEDO | G25: 45722 | H25: 2025 | I25: 2026 | J25: =DATE($H25,MONTH($G25),DAY($G25)) -> 45722 | K25: =DATE($H25+1,MONTH($G25),DAY($G25)) -> 46087 | L25: =DATE(YEAR($K25)+1,MONTH($K25),DAY($K25)) -> 46452 | M25: 7 | N25: 7 | O25: 46293 | P25: =IF(OR(O25="",N25=""),"",O25+N25-1) -> 46299 | Q25: =IF($J25="","",MAX(0,$M25-SUMIFS($N:$N,$J:$J,$J25,$K:$K,$K25))) -> 0 | R25: =IF(OR($M25="",$N25=""),"",IF($N25>$M25,"EXCEDE SALDO",IF(OR($O25="",$P25=""),"OK",IF($P25<$O25,"DATAS INVÁLIDAS",IF($P25>$L25,"FORA DO PRAZO","OK"))))) -> OK | S25: =IF(OR($M25="",$N25=""),"",IF($N25>$M25,"EXCEDE SALDO",IF(OR($O25="",$P25=""),"OK",IF($P25<$O25,"DATAS INVÁLIDAS",IF($P25>$L25,"FORA DO PRAZO","OK"))))) -> OK
B26: PHDE | C26: DIANY STEFFANE FERREIRA SANTANA | D26: ESPECIALISTA DE PLANEJAMENTO | E26: SILAS MOREIRA TUPINAMBÁ | F26: DIEGO FIRME BERNARDES | G26: 45511 | H26: 2024 | I26: 2025 | J26: =DATE($H26,MONTH($G26),DAY($G26)) -> 45511 | K26: =DATE($H26+1,MONTH($G26),DAY($G26)) -> 45876 | L26: 46387 | M26: 6 | N26: 6 | O26: 46118 | P26: =IF(OR(O26="",N26=""),"",O26+N26-1) -> 46123 | Q26: =IF($J26="","",MAX(0,$M26-SUMIFS($N:$N,$J:$J,$J26,$K:$K,$K26))) -> 0 | R26: =IF(OR($M26="",$N26=""),"",IF($N26>$M26,"EXCEDE SALDO",IF(OR($O26="",$P26=""),"OK",IF($P26<$O26,"DATAS INVÁLIDAS",IF($P26>$L26,"FORA DO PRAZO","OK"))))) -> OK | S26: =IF(OR($M26="",$N26=""),"",IF($N26>$M26,"EXCEDE SALDO",IF(OR($O26="",$P26=""),"OK",IF($P26<$O26,"DATAS INVÁLIDAS",IF($P26>$L26,"FORA DO PRAZO","OK"))))) -> OK
B27: PHDE | C27: DIANY STEFFANE FERREIRA SANTANA | D27: ESPECIALISTA DE PLANEJAMENTO | E27: SILAS MOREIRA TUPINAMBÁ | F27: DIEGO FIRME BERNARDES | G27: 45511 | H27: 2025 | I27: 2026 | J27: =DATE($H27,MONTH($G27),DAY($G27)) -> 45876 | K27: =DATE($H27+1,MONTH($G27),DAY($G27)) -> 46241 | L27: 46387 | M27: =(5*1.75) -> 8.75 | N27: =M27 -> 8.75 | O27: =P26+1 -> 46124 | P27: =IF(OR(O27="",N27=""),"",O27+N27-1) -> 46131.75 | Q27: =IF($J27="","",MAX(0,$M27-SUMIFS($N:$N,$J:$J,$J27,$K:$K,$K27))) -> 0 | R27: =IF(OR($M27="",$N27=""),"",IF($N27>$M27,"EXCEDE SALDO",IF(OR($O27="",$P27=""),"OK",IF($P27<$O27,"DATAS INVÁLIDAS",IF($P27>$L27,"FORA DO PRAZO","OK"))))) -> OK | S27: =IF(OR($M27="",$N27=""),"",IF($N27>$M27,"EXCEDE SALDO",IF(OR($O27="",$P27=""),"OK",IF($P27<$O27,"DATAS INVÁLIDAS",IF($P27>$L27,"FORA DO PRAZO","OK"))))) -> OK
B28: PHDE | C28: DIOGO HENRIQUE SOARES | D28: COORDENADOR DE PLANEJAMENTO | E28: LEONARDO AUGUSTO OLIVEIRA DRUMOND | F28: LEONARDO AUGUSTO OLIVEIRA DRUMOND | G28: 44907 | H28: 2024 | I28: 2025 | J28: =DATE($H28,MONTH($G28),DAY($G28)) -> 45638 | K28: =DATE($H28+1,MONTH($G28),DAY($G28)) -> 46003 | L28: =DATE(YEAR($K28)+1,MONTH($K28),DAY($K28)) -> 46368 | M28: 10 | N28: 10 | O28: 46316 | P28: =IF(OR(O28="",N28=""),"",O28+N28-1) -> 46325 | Q28: =IF($J28="","",MAX(0,$M28-SUMIFS($N:$N,$J:$J,$J28,$K:$K,$K28))) -> 0 | R28: =IF(OR($M28="",$N28=""),"",IF($N28>$M28,"EXCEDE SALDO",IF(OR($O28="",$P28=""),"OK",IF($P28<$O28,"DATAS INVÁLIDAS",IF($P28>$L28,"FORA DO PRAZO","OK"))))) -> OK | S28: =IF(OR($M28="",$N28=""),"",IF($N28>$M28,"EXCEDE SALDO",IF(OR($O28="",$P28=""),"OK",IF($P28<$O28,"DATAS INVÁLIDAS",IF($P28>$L28,"FORA DO PRAZO","OK"))))) -> OK
B29: PHDE | C29: DIOGO HENRIQUE SOARES | D29: COORDENADOR DE PLANEJAMENTO | E29: LEONARDO AUGUSTO OLIVEIRA DRUMOND | F29: LEONARDO AUGUSTO OLIVEIRA DRUMOND | G29: 44907 | H29: 2025 | I29: 2026 | J29: =DATE($H29,MONTH($G29),DAY($G29)) -> 46003 | K29: =DATE($H29+1,MONTH($G29),DAY($G29)) -> 46368 | L29: =DATE(YEAR($K29)+1,MONTH($K29),DAY($K29)) -> 46733 | M29: 21 | N29: 21 | O29: 46207 | P29: =IF(OR(O29="",N29=""),"",O29+N29-1) -> 46227 | Q29: =IF($J29="","",MAX(0,$M29-SUMIFS($N:$N,$J:$J,$J29,$K:$K,$K29))) -> 0 | R29: =IF(OR($M29="",$N29=""),"",IF($N29>$M29,"EXCEDE SALDO",IF(OR($O29="",$P29=""),"OK",IF($P29<$O29,"DATAS INVÁLIDAS",IF($P29>$L29,"FORA DO PRAZO","OK"))))) -> OK | S29: =IF(OR($M29="",$N29=""),"",IF($N29>$M29,"EXCEDE SALDO",IF(OR($O29="",$P29=""),"OK",IF($P29<$O29,"DATAS INVÁLIDAS",IF($P29>$L29,"FORA DO PRAZO","OK"))))) -> OK
B30: PHDE | C30: DIVINO FELICIO SANTOS | D30: CONSULTOR DE PLANEJAMENTO SR | E30: DIOGO HENRIQUE SOARES | F30: LEONARDO AUGUSTO OLIVEIRA DRUMOND | G30: 45889 | H30: 2025 | I30: 2026 | J30: =DATE($H30,MONTH($G30),DAY($G30)) -> 45889 | K30: =DATE($H30+1,MONTH($G30),DAY($G30)) -> 46254 | L30: 46387 | M30: 0 | N30: 0 | P30: =IF(OR(O30="",N30=""),"",O30+N30-1) | Q30: =IF($J30="","",MAX(0,$M30-SUMIFS($N:$N,$J:$J,$J30,$K:$K,$K30))) -> 0 | R30: =IF(OR($M30="",$N30=""),"",IF($N30>$M30,"EXCEDE SALDO",IF(OR($O30="",$P30=""),"OK",IF($P30<$O30,"DATAS INVÁLIDAS",IF($P30>$L30,"FORA DO PRAZO","OK"))))) -> OK | S30: =IF(OR($M30="",$N30=""),"",IF($N30>$M30,"EXCEDE SALDO",IF(OR($O30="",$P30=""),"OK",IF($P30<$O30,"DATAS INVÁLIDAS",IF($P30>$L30,"FORA DO PRAZO","OK"))))) -> OK
B31: PHDE | C31: EDUARDO FERREIRA DA SILVA | D31: COORDENADOR BIM | E31: RONALDO MENDES MACHADO | F31: BRUNO ALBERTO AZEVEDO | G31: 44768 | H31: 2024 | I31: 2025 | J31: =DATE($H31,MONTH($G31),DAY($G31)) -> 45499 | K31: =DATE($H31+1,MONTH($G31),DAY($G31)) -> 45864 | L31: =DATE(YEAR($K31)+1,MONTH($K31),DAY($K31)) -> 46229 | M31: 14 | N31: 14 | O31: 46132 | P31: =IF(OR(O31="",N31=""),"",O31+N31-1) -> 46145 | Q31: =IF($J31="","",MAX(0,$M31-SUMIFS($N:$N,$J:$J,$J31,$K:$K,$K31))) -> 0 | R31: =IF(OR($M31="",$N31=""),"",IF($N31>$M31,"EXCEDE SALDO",IF(OR($O31="",$P31=""),"OK",IF($P31<$O31,"DATAS INVÁLIDAS",IF($P31>$L31,"FORA DO PRAZO","OK"))))) -> OK | S31: =IF(OR($M31="",$N31=""),"",IF($N31>$M31,"EXCEDE SALDO",IF(OR($O31="",$P31=""),"OK",IF($P31<$O31,"DATAS INVÁLIDAS",IF($P31>$L31,"FORA DO PRAZO","OK"))))) -> OK
B32: PHDE | C32: EDUARDO FERREIRA DA SILVA | D32: COORDENADOR BIM | E32: RONALDO MENDES MACHADO | F32: BRUNO ALBERTO AZEVEDO | G32: 44768 | H32: 2024 | I32: 2025 | J32: =DATE($H32,MONTH($G32),DAY($G32)) -> 45499 | K32: =DATE($H32+1,MONTH($G32),DAY($G32)) -> 45864 | L32: =DATE(YEAR($K32)+1,MONTH($K32),DAY($K32)) -> 46229 | M32: 7 | N32: 7 | O32: 46216 | P32: =IF(OR(O32="",N32=""),"",O32+N32-1) -> 46222 | Q32: =IF($J32="","",MAX(0,$M32-SUMIFS($N:$N,$J:$J,$J32,$K:$K,$K32))) -> 0 | R32: =IF(OR($M32="",$N32=""),"",IF($N32>$M32,"EXCEDE SALDO",IF(OR($O32="",$P32=""),"OK",IF($P32<$O32,"DATAS INVÁLIDAS",IF($P32>$L32,"FORA DO PRAZO","OK"))))) -> OK | S32: =IF(OR($M32="",$N32=""),"",IF($N32>$M32,"EXCEDE SALDO",IF(OR($O32="",$P32=""),"OK",IF($P32<$O32,"DATAS INVÁLIDAS",IF($P32>$L32,"FORA DO PRAZO","OK"))))) -> OK
B33: PHDE | C33: EDUARDO FERREIRA DA SILVA | D33: COORDENADOR BIM | E33: RONALDO MENDES MACHADO | F33: BRUNO ALBERTO AZEVEDO | G33: 44768 | H33: 2025 | I33: 2026 | J33: =DATE($H33,MONTH($G33),DAY($G33)) -> 45864 | K33: =DATE($H33+1,MONTH($G33),DAY($G33)) -> 46229 | L33: =DATE(YEAR($K33)+1,MONTH($K33),DAY($K33)) -> 46594 | M33: 7 | N33: 7 | O33: =P32+1 -> 46223 | P33: =IF(OR(O33="",N33=""),"",O33+N33-1) -> 46229 | Q33: =IF($J33="","",MAX(0,$M33-SUMIFS($N:$N,$J:$J,$J33,$K:$K,$K33))) -> 0 | R33: =IF(OR($M33="",$N33=""),"",IF($N33>$M33,"EXCEDE SALDO",IF(OR($O33="",$P33=""),"OK",IF($P33<$O33,"DATAS INVÁLIDAS",IF($P33>$L33,"FORA DO PRAZO","OK"))))) -> OK | S33: =IF(OR($M33="",$N33=""),"",IF($N33>$M33,"EXCEDE SALDO",IF(OR($O33="",$P33=""),"OK",IF($P33<$O33,"DATAS INVÁLIDAS",IF($P33>$L33,"FORA DO PRAZO","OK"))))) -> OK
B34: PHDE | C34: EDUARDO FERREIRA DA SILVA | D34: COORDENADOR BIM | E34: RONALDO MENDES MACHADO | F34: BRUNO ALBERTO AZEVEDO | G34: 44768 | H34: 2025 | I34: 2026 | J34: =DATE($H34,MONTH($G34),DAY($G34)) -> 45864 | K34: =DATE($H34+1,MONTH($G34),DAY($G34)) -> 46229 | L34: =DATE(YEAR($K34)+1,MONTH($K34),DAY($K34)) -> 46594 | M34: 14 | N34: 14 | O34: 46384 | P34: =IF(OR(O34="",N34=""),"",O34+N34-1) -> 46397 | Q34: =IF($J34="","",MAX(0,$M34-SUMIFS($N:$N,$J:$J,$J34,$K:$K,$K34))) -> 0 | R34: =IF(OR($M34="",$N34=""),"",IF($N34>$M34,"EXCEDE SALDO",IF(OR($O34="",$P34=""),"OK",IF($P34<$O34,"DATAS INVÁLIDAS",IF($P34>$L34,"FORA DO PRAZO","OK"))))) -> OK | S34: =IF(OR($M34="",$N34=""),"",IF($N34>$M34,"EXCEDE SALDO",IF(OR($O34="",$P34=""),"OK",IF($P34<$O34,"DATAS INVÁLIDAS",IF($P34>$L34,"FORA DO PRAZO","OK"))))) -> OK
B35: PHDE | C35: EMERSON DE MELO FERREIRA DA SILVA | D35: CONSULTOR DE PLANEJAMENTO | E35: ALESSANDRO PEREIRA MOREIRA | F35: DIEGO FIRME BERNARDES | G35: 45839 | H35: 2025 | I35: 2026 | J35: =DATE($H35,MONTH($G35),DAY($G35)) -> 45839 | K35: =DATE($H35+1,MONTH($G35),DAY($G35)) -> 46204 | L35: 46387 | M35: 11 | N35: 11 | O35: 46216 | P35: =IF(OR(O35="",N35=""),"",O35+N35-1) -> 46226 | Q35: =IF($J35="","",MAX(0,$M35-SUMIFS($N:$N,$J:$J,$J35,$K:$K,$K35))) -> 0 | R35: =IF(OR($M35="",$N35=""),"",IF($N35>$M35,"EXCEDE SALDO",IF(OR($O35="",$P35=""),"OK",IF($P35<$O35,"DATAS INVÁLIDAS",IF($P35>$L35,"FORA DO PRAZO","OK"))))) -> OK | S35: =IF(OR($M35="",$N35=""),"",IF($N35>$M35,"EXCEDE SALDO",IF(OR($O35="",$P35=""),"OK",IF($P35<$O35,"DATAS INVÁLIDAS",IF($P35>$L35,"FORA DO PRAZO","OK"))))) -> OK
B36: PHDE | C36: FABIO DE JESUS OLIVEIRA | D36: CONSULTOR DE PLANEJAMENTO SR | E36: RONALDO MENDES MACHADO | F36: BRUNO ALBERTO AZEVEDO | G36: 44697 | H36: 2024 | I36: 2025 | J36: =DATE($H36,MONTH($G36),DAY($G36)) -> 45428 | K36: =DATE($H36+1,MONTH($G36),DAY($G36)) -> 45793 | L36: =DATE(YEAR($K36)+1,MONTH($K36),DAY($K36)) -> 46158 | M36: 19 | N36: 19 | O36: 46237 | P36: =IF(OR(O36="",N36=""),"",O36+N36-1) -> 46255 | Q36: =IF($J36="","",MAX(0,$M36-SUMIFS($N:$N,$J:$J,$J36,$K:$K,$K36))) -> 0 | R36: =IF(OR($M36="",$N36=""),"",IF($N36>$M36,"EXCEDE SALDO",IF(OR($O36="",$P36=""),"OK",IF($P36<$O36,"DATAS INVÁLIDAS",IF($P36>$L36,"FORA DO PRAZO","OK"))))) -> FORA DO PRAZO | S36: =IF(OR($M36="",$N36=""),"",IF($N36>$M36,"EXCEDE SALDO",IF(OR($O36="",$P36=""),"OK",IF($P36<$O36,"DATAS INVÁLIDAS",IF($P36>$L36,"FORA DO PRAZO","OK"))))) -> FORA DO PRAZO
B37: PHDE | C37: FABIO DE JESUS OLIVEIRA | D37: CONSULTOR DE PLANEJAMENTO SR | E37: RONALDO MENDES MACHADO | F37: BRUNO ALBERTO AZEVEDO | G37: 44697 | H37: 2025 | I37: 2026 | J37: =DATE($H37,MONTH($G37),DAY($G37)) -> 45793 | K37: =DATE($H37+1,MONTH($G37),DAY($G37)) -> 46158 | L37: =DATE(YEAR($K37)+1,MONTH($K37),DAY($K37)) -> 46523 | M37: 21 | N37: 7 | O37: 46146 | P37: =IF(OR(O37="",N37=""),"",O37+N37-1) -> 46152 | Q37: =IF($J37="","",MAX(0,$M37-SUMIFS($N:$N,$J:$J,$J37,$K:$K,$K37))) -> 0 | R37: =IF(OR($M37="",$N37=""),"",IF($N37>$M37,"EXCEDE SALDO",IF(OR($O37="",$P37=""),"OK",IF($P37<$O37,"DATAS INVÁLIDAS",IF($P37>$L37,"FORA DO PRAZO","OK"))))) -> OK | S37: =IF(OR($M37="",$N37=""),"",IF($N37>$M37,"EXCEDE SALDO",IF(OR($O37="",$P37=""),"OK",IF($P37<$O37,"DATAS INVÁLIDAS",IF($P37>$L37,"FORA DO PRAZO","OK"))))) -> OK
B38: PHDE | C38: FABIO DE JESUS OLIVEIRA | D38: CONSULTOR DE PLANEJAMENTO SR | E38: RONALDO MENDES MACHADO | F38: BRUNO ALBERTO AZEVEDO | G38: 44697 | H38: 2025 | I38: 2026 | J38: =DATE($H38,MONTH($G38),DAY($G38)) -> 45793 | K38: =DATE($H38+1,MONTH($G38),DAY($G38)) -> 46158 | L38: =DATE(YEAR($K38)+1,MONTH($K38),DAY($K38)) -> 46523 | M38: 14 | N38: 7 | O38: 46195 | P38: =IF(OR(O38="",N38=""),"",O38+N38-1) -> 46201 | Q38: =IF($J38="","",MAX(0,$M38-SUMIFS($N:$N,$J:$J,$J38,$K:$K,$K38))) -> 0 | R38: =IF(OR($M38="",$N38=""),"",IF($N38>$M38,"EXCEDE SALDO",IF(OR($O38="",$P38=""),"OK",IF($P38<$O38,"DATAS INVÁLIDAS",IF($P38>$L38,"FORA DO PRAZO","OK"))))) -> OK | S38: =IF(OR($M38="",$N38=""),"",IF($N38>$M38,"EXCEDE SALDO",IF(OR($O38="",$P38=""),"OK",IF($P38<$O38,"DATAS INVÁLIDAS",IF($P38>$L38,"FORA DO PRAZO","OK"))))) -> OK
B39: PHDE | C39: FABIO DE JESUS OLIVEIRA | D39: CONSULTOR DE PLANEJAMENTO SR | E39: RONALDO MENDES MACHADO | F39: BRUNO ALBERTO AZEVEDO | G39: 44697 | H39: 2025 | I39: 2026 | J39: =DATE($H39,MONTH($G39),DAY($G39)) -> 45793 | K39: =DATE($H39+1,MONTH($G39),DAY($G39)) -> 46158 | L39: =DATE(YEAR($K39)+1,MONTH($K39),DAY($K39)) -> 46523 | M39: 7 | N39: 7 | O39: 46370 | P39: =IF(OR(O39="",N39=""),"",O39+N39-1) -> 46376 | Q39: =IF($J39="","",MAX(0,$M39-SUMIFS($N:$N,$J:$J,$J39,$K:$K,$K39))) -> 0 | R39: =IF(OR($M39="",$N39=""),"",IF($N39>$M39,"EXCEDE SALDO",IF(OR($O39="",$P39=""),"OK",IF($P39<$O39,"DATAS INVÁLIDAS",IF($P39>$L39,"FORA DO PRAZO","OK"))))) -> OK | S39: =IF(OR($M39="",$N39=""),"",IF($N39>$M39,"EXCEDE SALDO",IF(OR($O39="",$P39=""),"OK",IF($P39<$O39,"DATAS INVÁLIDAS",IF($P39>$L39,"FORA DO PRAZO","OK"))))) -> OK
B40: PHDE | C40: FELIPE SANTOS ARAUJO | D40: ESPECIALISTA DE PLANEJAMENTO | E40: DIOGO HENRIQUE SOARES | F40: LEONARDO AUGUSTO OLIVEIRA DRUMOND | G40: 45936 | H40: 2025 | I40: 2026 | J40: =DATE($H40,MONTH($G40),DAY($G40)) -> 45936 | K40: =DATE($H40+1,MONTH($G40),DAY($G40)) -> 46301 | L40: =DATE(YEAR($K40)+1,MONTH($K40),DAY($K40)) -> 46666 | M40: 0 | N40: 0 | P40: =IF(OR(O40="",N40=""),"",O40+N40-1) | Q40: =IF($J40="","",MAX(0,$M40-SUMIFS($N:$N,$J:$J,$J40,$K:$K,$K40))) -> 0 | R40: =IF(OR($M40="",$N40=""),"",IF($N40>$M40,"EXCEDE SALDO",IF(OR($O40="",$P40=""),"OK",IF($P40<$O40,"DATAS INVÁLIDAS",IF($P40>$L40,"FORA DO PRAZO","OK"))))) -> OK | S40: =IF(OR($M40="",$N40=""),"",IF($N40>$M40,"EXCEDE SALDO",IF(OR($O40="",$P40=""),"OK",IF($P40<$O40,"DATAS INVÁLIDAS",IF($P40>$L40,"FORA DO PRAZO","OK"))))) -> OK
...

Sheet Planilha2
A1: LIDER DIRETO | B1: GERENCIA/DIRETORIA | F1: Rótulos de Linha
A2: TULIO RAFAEL MORAIS | B2: LEONARDO AUGUSTO OLIVEIRA DRUMOND | F2: ALESSANDRO PEREIRA MOREIRA | G2: OK
A3: TULIO RAFAEL MORAIS | B3: LEONARDO AUGUSTO OLIVEIRA DRUMOND | F3: ALEX POSSIDONIO DA SILVA | G3: NÃO TEM
A4: EDUARDO DOS REIS ELER | B4: EDUARDO REIS ELER | F4: DIEGO FIRME BERNARDES
A5: LUCAS ANDRADE BATISTA | B5: PEDRO HENRIQUE BRAGA DE MORAIS | F5: DIOGO HENRIQUE SOARES
A6: DIEGO FIRME BERNARDES | B6: DIEGO FIRME BERNARDES | F6: EDUARDO DOS REIS ELER | G6: VAI INFORMAR
A7: THALES SANDER CARVALHO DE PÁDUA | B7: EDUARDO REIS ELER | F7: JULIO CESAR | G7: VAI INFORMAR
A8: THALES SANDER CARVALHO DE PÁDUA | B8: EDUARDO REIS ELER | F8: LEONARDO AUGUSTO OLIVEIRA DRUMOND
A9: THALES SANDER CARVALHO DE PÁDUA | B9: EDUARDO REIS ELER | F9: LUCAS ANDRADE BATISTA | G9: OK
A10: THALES SANDER CARVALHO DE PÁDUA | B10: EDUARDO REIS ELER | F10: MATEUS FILIPE CORRADI DE MORAIS
A11: ALEX POSSIDONIO DA SILVA | B11: DIEGO FIRME BERNARDES | F11: PAULO CEZAR DE PAIVA NETO | G11: vai ser coordenadores
A12: ALESSANDRO PEREIRA MOREIRA | B12: LEONARDO AUGUSTO OLIVEIRA DRUMOND | F12: PEDRO HENRIQUE BOSCO NERY | G12: EXCLUIDO
A13: ALESSANDRO PEREIRA MOREIRA | B13: LEONARDO AUGUSTO OLIVEIRA DRUMOND | F13: SILAS MOREIRA TUPINAMBÁ
A14: PAULO CEZAR DE PAIVA NETO | B14: PAULO CEZAR DE PAIVA NETO | F14: THALES SANDER CARVALHO DE PÁDUA | G14: VAI INFORMAR
A15: DIEGO FIRME BERNARDES | B15: PEDRO HENRIQUE BRAGA DE MORAIS | F15: TULIO RAFAEL MORAIS | G15: OK
A16: DIEGO FIRME BERNARDES | B16: PEDRO HENRIQUE BRAGA DE MORAIS | F16: (vazio)
A17: EDUARDO DOS REIS ELER | B17: EDUARDO REIS ELER | F17: Total Geral
A18: TULIO RAFAEL MORAIS | B18: LEONARDO AUGUSTO OLIVEIRA DRUMOND
A19: DIOGO HENRIQUE SOARES | B19: LEONARDO AUGUSTO OLIVEIRA DRUMOND
A20: EDUARDO DOS REIS ELER | B20: PEDRO HENRIQUE BRAGA DE MORAIS
A21: EDUARDO DOS REIS ELER | B21: PEDRO HENRIQUE BRAGA DE MORAIS
A22: ALESSANDRO PEREIRA MOREIRA | B22: DIEGO FIRME BERNARDES
A23: TULIO RAFAEL MORAIS | B23: LEONARDO AUGUSTO OLIVEIRA DRUMOND
A24: DIOGO HENRIQUE SOARES | B24: LEONARDO AUGUSTO OLIVEIRA DRUMOND
A25: JULIO CESAR | B25: JULIO CESAR
A26: JULIO CESAR | B26: PAULO CEZAR DE PAIVA NETO
A27: JULIO CESAR | B27: PAULO CEZAR DE PAIVA NETO
A28: PAULO CEZAR DE PAIVA NETO | B28: PAULO CEZAR DE PAIVA NETO
A29: PAULO CEZAR DE PAIVA NETO | B29: PAULO CEZAR DE PAIVA NETO
... A92: EDUARDO DOS REIS ELER | B92: EDUARDO REIS ELER

Sheet Planilha1
A1: ADAILTON LUCAS GALINDO DE ANDRADE | B1: =VLOOKUP(A1,'PLANILHA MODELO'!C:C,1,0) -> ADAILTON LUCAS GALINDO DE ANDRADE
A2: ANDREY LUZ SOUSA | B2: =VLOOKUP(A2,'PLANILHA MODELO'!C:C,1,0) -> #N/A
A3: ANGELA MARIA LOPES CAMPOS | B3: =VLOOKUP(A3,'PLANILHA MODELO'!C:C,1,0) -> #N/A
A4: ARTHUR FARHAT BENEDITO | B4: =VLOOKUP(A4,'PLANILHA MODELO'!C:C,1,0) -> ARTHUR FARHAT BENEDITO
A5: ARTUR VIEIRA JANUTH | B5: =VLOOKUP(A5,'PLANILHA MODELO'!C:C,1,0) -> ARTUR VIEIRA JANUTH
A6: DANIEL CARLOS SILVA | B6: =VLOOKUP(A6,'PLANILHA MODELO'!C:C,1,0) -> DANIEL CARLOS SILVA
A7: DEIVIDY ALVES GOMES | B7: =VLOOKUP(A7,'PLANILHA MODELO'!C:C,1,0) -> #N/A
A8: DIANY STEFFANE FERREIRA SANTANA | B8: =VLOOKUP(A8,'PLANILHA MODELO'!C:C,1,0) -> DIANY STEFFANE FERREIRA SANTANA
A9: DIEGO RANIERI MELO RODRIGUES | B9: =VLOOKUP(A9,'PLANILHA MODELO'!C:C,1,0) -> #N/A
A10: DIVINO FELICIO SANTOS | B10: =VLOOKUP(A10,'PLANILHA MODELO'!C:C,1,0) -> DIVINO FELICIO SANTOS
A11: EMERSON DE MELO FERREIRA DA SILVA | B11: =VLOOKUP(A11,'PLANILHA MODELO'!C:C,1,0) -> EMERSON DE MELO FERREIRA DA SILVA
A12: FERNANDA LOPES DE LIGORIO | B12: =VLOOKUP(A12,'PLANILHA MODELO'!C:C,1,0) -> #N/A
... A33: WARLEY SANTOS MARTINS NOGUEIRA | B33: =VLOOKUP(A33,'PLANILHA MODELO'!C:C,1,0) -> WARLEY SANTOS MARTINS NOGUEIRA
